2025-01-08 15:49:31,416 - ERROR - __init__.py - An error occurred while connecting to the database: Invalid connection string, Please follow the format: Server=server_name;Database=database_name;UID=user_name;PWD=password
2025-01-08 15:49:56,743 - ERROR - __init__.py - An error occurred while connecting to the database: Invalid connection string, Please follow the format: Server=server_name;Database=database_name;UID=user_name;PWD=password
2025-01-08 15:50:21,639 - ERROR - __init__.py - An error occurred while connecting to the database: Invalid connection string, Please follow the format: Server=server_name;Database=database_name;UID=user_name;PWD=password
2025-01-08 15:51:17,374 - ERROR - connection.py - An error occurred while connecting to the database: exception: access violation reading 0x0000000000000048
2025-01-08 15:51:17,375 - ERROR - __init__.py - An error occurred while connecting to the database: exception: access violation reading 0x0000000000000048
2025-01-08 15:54:26,657 - ERROR - connection.py - An error occurred during initialization: check_ret() missing 1 required positional argument: 'handle'
2025-01-08 15:54:26,658 - ERROR - connection.py - An error occurred while connecting to the database: exception: access violation reading 0x0000000000000048
2025-01-08 15:54:26,659 - ERROR - __init__.py - An error occurred while connecting to the database: exception: access violation reading 0x0000000000000048
2025-01-08 15:55:06,128 - ERROR - connection.py - An error occurred during initialization: check_ret() missing 1 required positional argument: 'handle'
2025-01-08 15:55:06,129 - ERROR - connection.py - An error occurred while connecting to the database: exception: access violation reading 0x0000000000000048
2025-01-08 15:55:06,129 - ERROR - __init__.py - An error occurred while connecting to the database: exception: access violation reading 0x0000000000000048
2025-01-08 15:58:06,504 - ERROR - connection.py - An error occurred during initialization: check_ret() missing 1 required positional argument: 'handle'
2025-01-08 15:58:06,504 - ERROR - connection.py - An error occurred while connecting to the database: exception: access violation reading 0x0000000000000048
2025-01-08 15:58:06,504 - ERROR - __init__.py - An error occurred while connecting to the database: exception: access violation reading 0x0000000000000048
2025-01-08 15:58:30,168 - ERROR - connection.py - An error occurred during initialization: check_ret() missing 1 required positional argument: 'handle'
2025-01-08 15:58:30,168 - ERROR - connection.py - An error occurred while connecting to the database: exception: access violation reading 0x0000000000000048
2025-01-08 15:58:30,170 - ERROR - __init__.py - An error occurred while connecting to the database: exception: access violation reading 0x0000000000000048
2025-01-08 15:58:44,874 - ERROR - connection.py - An error occurred during initialization: check_ret() missing 1 required positional argument: 'handle'
2025-01-08 15:58:44,874 - INFO - __init__.py - Successfully connected to the database
2025-01-08 15:58:44,874 - ERROR - connection.py - An error occurred while connecting to the database: exception: access violation reading 0x0000000000000048
2025-01-08 15:58:44,874 - ERROR - __init__.py - An error occurred while connecting to the database: exception: access violation reading 0x0000000000000048
2025-01-08 15:59:13,905 - ERROR - connection.py - An error occurred during initialization: check_ret() missing 1 required positional argument: 'handle'
2025-01-08 15:59:13,905 - INFO - __init__.py - Successfully connected to the database
2025-01-08 15:59:13,905 - ERROR - connection.py - An error occurred while connecting to the database: exception: access violation reading 0x0000000000000048
2025-01-08 15:59:13,907 - ERROR - __init__.py - An error occurred while connecting to the database: exception: access violation reading 0x0000000000000048
2025-01-08 15:59:47,652 - INFO - connection.py - ODBC environment and connection handles initialized successfully.
2025-01-08 15:59:47,657 - ERROR - connection.py - An error occurred during initialization: check_ret() missing 1 required positional argument: 'handle'
2025-01-08 15:59:47,657 - INFO - __init__.py - Successfully connected to the database
2025-01-08 15:59:47,657 - ERROR - connection.py - An error occurred while connecting to the database: exception: access violation reading 0x0000000000000048
2025-01-08 15:59:47,657 - ERROR - __init__.py - An error occurred while connecting to the database: exception: access violation reading 0x0000000000000048
2025-01-08 16:00:03,336 - INFO - connection.py - ODBC environment and connection handles initialized successfully.
2025-01-08 16:00:03,346 - ERROR - connection.py - An error occurred during initialization: check_ret() missing 1 required positional argument: 'handle'
2025-01-08 16:00:03,347 - INFO - connection.py - Connecting to the database
2025-01-08 16:00:03,347 - INFO - __init__.py - Successfully connected to the database
2025-01-08 16:00:03,347 - ERROR - connection.py - An error occurred while connecting to the database: exception: access violation reading 0x0000000000000048
2025-01-08 16:00:03,347 - ERROR - __init__.py - An error occurred while connecting to the database: exception: access violation reading 0x0000000000000048
2025-01-08 16:00:29,506 - ERROR - __init__.py - An error occurred while connecting to the database: check_ret() missing 1 required positional argument: 'handle'
2025-01-08 16:01:33,595 - ERROR - __init__.py - An error occurred while connecting to the database: object of type 'int' has no len()
2025-01-08 16:02:31,795 - INFO - connection.py - Connecting to the database
2025-01-08 16:02:31,795 - INFO - __init__.py - Connecting to the database
2025-01-08 16:02:46,898 - ERROR - connection.py - An error occurred while connecting to the database: function 'SQLSMALLINT' not found
2025-01-08 16:02:46,899 - ERROR - __init__.py - An error occurred while connecting to the database: function 'SQLSMALLINT' not found
2025-01-08 16:03:27,875 - INFO - connection.py - Connecting to the database
2025-01-08 16:03:27,878 - INFO - __init__.py - Connecting to the database
2025-01-08 16:03:28,396 - INFO - connection.py - Connection established successfully.
2025-01-08 16:47:29,086 - INFO - connection.py - Connecting to the database
2025-01-08 16:47:29,088 - INFO - __init__.py - Connecting to the database
2025-01-08 16:47:44,334 - ERROR - connection.py - An error occurred while connecting to the database: 'c_wchar_Array_6' object has no attribute 'GENERAL_WARNING'
2025-01-08 16:47:44,334 - ERROR - __init__.py - An error occurred while connecting to the database: 'c_wchar_Array_6' object has no attribute 'GENERAL_WARNING'
2025-01-08 16:49:01,321 - INFO - connection.py - Connecting to the database
2025-01-08 16:49:01,322 - INFO - __init__.py - Connecting to the database
2025-01-08 16:49:20,733 - ERROR - connection.py - An error occurred while connecting to the database: 'c_wchar_Array_6' object has no attribute 'GENERAL_WARNING'
2025-01-08 16:49:20,733 - ERROR - __init__.py - An error occurred while connecting to the database: 'c_wchar_Array_6' object has no attribute 'GENERAL_WARNING'
2025-01-08 16:50:02,845 - INFO - connection.py - Connecting to the database
2025-01-08 16:50:02,846 - INFO - __init__.py - Connecting to the database
2025-01-08 16:50:18,351 - ERROR - connection.py - An error occurred while connecting to the database: ODBC error: [Microsoft][ODBC Driver 18 for SQL Server][SQL Server]Cannot open server 'pythontest1' requested by the login. Client with IP address '167.220.238.131' is not allowed to access the server.  To enable access, use the Azure Management Portal or run sp_set_firewall_rule on the master database to create a firewall rule for this IP address or address range.  It may take up to five minutes for this change to take effect. (SQL State: 42000)
2025-01-08 16:50:18,353 - ERROR - __init__.py - An error occurred while connecting to the database: ODBC error: [Microsoft][ODBC Driver 18 for SQL Server][SQL Server]Cannot open server 'pythontest1' requested by the login. Client with IP address '167.220.238.131' is not allowed to access the server.  To enable access, use the Azure Management Portal or run sp_set_firewall_rule on the master database to create a firewall rule for this IP address or address range.  It may take up to five minutes for this change to take effect. (SQL State: 42000)
2025-01-08 16:52:16,716 - INFO - connection.py - Connecting to the database
2025-01-08 16:52:16,717 - INFO - __init__.py - Connecting to the database
2025-01-08 16:52:27,195 - ERROR - connection.py - An error occurred while connecting to the database: ODBC error: [Microsoft][ODBC Driver 18 for SQL Server][SQL Server]Failed to authenticate the user 'sqladmin@jahnvithakkar2000gmail.onmicrosoft.com' in Active Directory (Authentication option is 'ActiveDirectoryInteractive').
Error code 0x4C7; state 10
The operation was canceled by the user. (SQL State: FA004)
2025-01-08 16:52:27,195 - ERROR - __init__.py - An error occurred while connecting to the database: ODBC error: [Microsoft][ODBC Driver 18 for SQL Server][SQL Server]Failed to authenticate the user 'sqladmin@jahnvithakkar2000gmail.onmicrosoft.com' in Active Directory (Authentication option is 'ActiveDirectoryInteractive').
Error code 0x4C7; state 10
The operation was canceled by the user. (SQL State: FA004)
2025-01-08 16:52:55,996 - INFO - connection.py - Connecting to the database
2025-01-08 16:52:55,996 - INFO - __init__.py - Connecting to the database
2025-01-08 16:52:56,354 - ERROR - connection.py - An error occurred while connecting to the database: ODBC error: [Microsoft][ODBC Driver 18 for SQL Server][SQL Server]Cannot open server "jahnvithakkar2000gmail.onmicrosoft.com" requested by the login.  The login failed. (SQL State: HY000)
2025-01-08 16:52:56,355 - ERROR - __init__.py - An error occurred while connecting to the database: ODBC error: [Microsoft][ODBC Driver 18 for SQL Server][SQL Server]Cannot open server "jahnvithakkar2000gmail.onmicrosoft.com" requested by the login.  The login failed. (SQL State: HY000)
2025-01-08 16:54:24,505 - INFO - connection.py - Connecting to the database
2025-01-08 16:54:24,505 - INFO - __init__.py - Connecting to the database
2025-01-08 16:54:25,159 - ERROR - connection.py - An error occurred while connecting to the database: ODBC error: [Microsoft][ODBC Driver 18 for SQL Server][SQL Server]Login failed for user 'sqladmin'. Reason: Azure Active Directory only authentication is enabled. Please contact your system administrator. (SQL State: 28000)
2025-01-08 16:54:25,160 - ERROR - __init__.py - An error occurred while connecting to the database: ODBC error: [Microsoft][ODBC Driver 18 for SQL Server][SQL Server]Login failed for user 'sqladmin'. Reason: Azure Active Directory only authentication is enabled. Please contact your system administrator. (SQL State: 28000)
2025-01-08 16:55:54,717 - INFO - connection.py - Connecting to the database
2025-01-08 16:55:54,719 - INFO - __init__.py - Connecting to the database
2025-01-08 16:56:09,921 - ERROR - connection.py - An error occurred while connecting to the database: ODBC error: [Microsoft][ODBC Driver 18 for SQL Server]TCP Provider: Timeout error [258].  (SQL State: 08001)
2025-01-08 16:56:09,922 - ERROR - __init__.py - An error occurred while connecting to the database: ODBC error: [Microsoft][ODBC Driver 18 for SQL Server]TCP Provider: Timeout error [258].  (SQL State: 08001)
2025-01-08 16:56:14,116 - INFO - connection.py - Connecting to the database
2025-01-08 16:56:14,117 - INFO - __init__.py - Connecting to the database
2025-01-08 16:56:29,279 - ERROR - connection.py - An error occurred while connecting to the database: ODBC error: [Microsoft][ODBC Driver 18 for SQL Server]TCP Provider: Timeout error [258].  (SQL State: 08001)
2025-01-08 16:56:29,280 - ERROR - __init__.py - An error occurred while connecting to the database: ODBC error: [Microsoft][ODBC Driver 18 for SQL Server]TCP Provider: Timeout error [258].  (SQL State: 08001)
2025-01-08 16:56:33,191 - INFO - connection.py - Connecting to the database
2025-01-08 16:56:33,192 - INFO - __init__.py - Connecting to the database
2025-01-08 16:56:43,882 - INFO - connection.py - Connection established successfully.
2025-01-08 16:58:33,473 - INFO - connection.py - Connecting to the database
2025-01-08 16:58:33,474 - INFO - __init__.py - Connecting to the database
2025-01-08 16:58:35,509 - INFO - connection.py - Connection established successfully.
2025-01-08 19:32:37,214 - INFO - connection.py - Connecting to the database
2025-01-08 19:32:37,214 - INFO - __init__.py - Connecting to the database
2025-01-08 19:32:54,975 - INFO - connection.py - Connection established successfully.
2025-01-09 16:29:16,282 - INFO - connection.py - Connecting to the database
2025-01-09 16:29:16,297 - INFO - __init__.py - Connecting to the database
2025-01-09 16:29:31,487 - ERROR - connection.py - An error occurred while connecting to the database: ODBC error: [Microsoft][ODBC Driver 18 for SQL Server][SQL Server]Error 12029 opening URL http://169.254.169.254/metadata/identity/oauth2/token?api-version=2018-02-01&resource=https%3A%2F%2Fdatabase.windows.net%2F&object_id=a7e32f8f-dde5-4a0e-b2c7-6699649cf11f (SQL State: CE267)
2025-01-09 16:29:31,487 - ERROR - __init__.py - An error occurred while connecting to the database: ODBC error: [Microsoft][ODBC Driver 18 for SQL Server][SQL Server]Error 12029 opening URL http://169.254.169.254/metadata/identity/oauth2/token?api-version=2018-02-01&resource=https%3A%2F%2Fdatabase.windows.net%2F&object_id=a7e32f8f-dde5-4a0e-b2c7-6699649cf11f (SQL State: CE267)
2025-01-10 14:12:10,466 - ERROR - __init__.py - An error occurred while connecting to the database: SQLAllocHandle(): incompatible function arguments. The following argument types are supported:
    1. (arg0: int, arg1: int, arg2: int) -> int

Invoked with: 1, None, <cparam 'P' (0x000001B9BCD4C518)>
2025-01-10 14:17:59,723 - INFO - connection.py - Connecting to the database
2025-01-10 14:17:59,726 - INFO - __init__.py - Connecting to the database
2025-01-10 14:18:01,819 - INFO - connection.py - Connection established successfully.
2025-01-10 14:22:47,587 - INFO - connection.py - Connection established successfully.
2025-01-10 14:22:47,740 - INFO - connection.py - Connecting to the database
2025-01-10 14:22:47,741 - INFO - __init__.py - Connecting to the database
2025-01-10 14:22:49,068 - INFO - connection.py - Connection established successfully.
2025-01-10 14:23:18,499 - INFO - connection.py - Connection established successfully.
2025-01-10 14:23:18,582 - INFO - connection.py - Connecting to the database
2025-01-10 14:23:18,582 - INFO - __init__.py - Connecting to the database
2025-01-10 14:23:20,106 - INFO - connection.py - Connection established successfully.
2025-01-10 14:28:34,594 - INFO - connection.py - Connection established successfully.
2025-01-10 14:28:34,595 - INFO - connection.py - Connecting to the database
2025-01-10 14:28:34,596 - INFO - utils.py - Connecting to the database
2025-01-10 14:28:36,342 - INFO - connection.py - Connection established successfully.
2025-01-10 14:40:19,819 - INFO - connection.py - Connection established successfully.
2025-01-10 14:40:19,819 - INFO - connection.py - Connecting to the database
2025-01-10 14:40:19,827 - INFO - utils.py - Connecting to the database
2025-01-10 14:40:21,082 - INFO - connection.py - Connection established successfully.
2025-01-10 15:11:02,110 - INFO - connection.py - Connection established successfully.
2025-01-10 15:11:02,162 - INFO - connection.py - Connecting to the database
2025-01-10 15:11:02,162 - INFO - utils.py - Connecting to the database
2025-01-10 15:11:03,347 - INFO - connection.py - Connection established successfully.
2025-01-10 15:11:48,957 - INFO - connection.py - Connection established successfully.
2025-01-10 15:11:48,998 - INFO - connection.py - Connecting to the database
2025-01-10 15:11:48,999 - INFO - utils.py - Connecting to the database
2025-01-10 15:11:50,675 - INFO - connection.py - Connection established successfully.
