2025-01-08 15:49:31,416 - ERROR - __init__.py - An error occurred while connecting to the database: Invalid connection string, Please follow the format: Server=server_name;Database=database_name;UID=user_name;PWD=password
2025-01-08 15:49:56,743 - ERROR - __init__.py - An error occurred while connecting to the database: Invalid connection string, Please follow the format: Server=server_name;Database=database_name;UID=user_name;PWD=password
2025-01-08 15:50:21,639 - ERROR - __init__.py - An error occurred while connecting to the database: Invalid connection string, Please follow the format: Server=server_name;Database=database_name;UID=user_name;PWD=password
2025-01-08 15:51:17,374 - ERROR - connection.py - An error occurred while connecting to the database: exception: access violation reading 0x0000000000000048
2025-01-08 15:51:17,375 - ERROR - __init__.py - An error occurred while connecting to the database: exception: access violation reading 0x0000000000000048
2025-01-08 15:54:26,657 - ERROR - connection.py - An error occurred during initialization: check_ret() missing 1 required positional argument: 'handle'
2025-01-08 15:54:26,658 - ERROR - connection.py - An error occurred while connecting to the database: exception: access violation reading 0x0000000000000048
2025-01-08 15:54:26,659 - ERROR - __init__.py - An error occurred while connecting to the database: exception: access violation reading 0x0000000000000048
2025-01-08 15:55:06,128 - ERROR - connection.py - An error occurred during initialization: check_ret() missing 1 required positional argument: 'handle'
2025-01-08 15:55:06,129 - ERROR - connection.py - An error occurred while connecting to the database: exception: access violation reading 0x0000000000000048
2025-01-08 15:55:06,129 - ERROR - __init__.py - An error occurred while connecting to the database: exception: access violation reading 0x0000000000000048
2025-01-08 15:58:06,504 - ERROR - connection.py - An error occurred during initialization: check_ret() missing 1 required positional argument: 'handle'
2025-01-08 15:58:06,504 - ERROR - connection.py - An error occurred while connecting to the database: exception: access violation reading 0x0000000000000048
2025-01-08 15:58:06,504 - ERROR - __init__.py - An error occurred while connecting to the database: exception: access violation reading 0x0000000000000048
2025-01-08 15:58:30,168 - ERROR - connection.py - An error occurred during initialization: check_ret() missing 1 required positional argument: 'handle'
2025-01-08 15:58:30,168 - ERROR - connection.py - An error occurred while connecting to the database: exception: access violation reading 0x0000000000000048
2025-01-08 15:58:30,170 - ERROR - __init__.py - An error occurred while connecting to the database: exception: access violation reading 0x0000000000000048
2025-01-08 15:58:44,874 - ERROR - connection.py - An error occurred during initialization: check_ret() missing 1 required positional argument: 'handle'
2025-01-08 15:58:44,874 - INFO - __init__.py - Successfully connected to the database
2025-01-08 15:58:44,874 - ERROR - connection.py - An error occurred while connecting to the database: exception: access violation reading 0x0000000000000048
2025-01-08 15:58:44,874 - ERROR - __init__.py - An error occurred while connecting to the database: exception: access violation reading 0x0000000000000048
2025-01-08 15:59:13,905 - ERROR - connection.py - An error occurred during initialization: check_ret() missing 1 required positional argument: 'handle'
2025-01-08 15:59:13,905 - INFO - __init__.py - Successfully connected to the database
2025-01-08 15:59:13,905 - ERROR - connection.py - An error occurred while connecting to the database: exception: access violation reading 0x0000000000000048
2025-01-08 15:59:13,907 - ERROR - __init__.py - An error occurred while connecting to the database: exception: access violation reading 0x0000000000000048
2025-01-08 15:59:47,652 - INFO - connection.py - ODBC environment and connection handles initialized successfully.
2025-01-08 15:59:47,657 - ERROR - connection.py - An error occurred during initialization: check_ret() missing 1 required positional argument: 'handle'
2025-01-08 15:59:47,657 - INFO - __init__.py - Successfully connected to the database
2025-01-08 15:59:47,657 - ERROR - connection.py - An error occurred while connecting to the database: exception: access violation reading 0x0000000000000048
2025-01-08 15:59:47,657 - ERROR - __init__.py - An error occurred while connecting to the database: exception: access violation reading 0x0000000000000048
2025-01-08 16:00:03,336 - INFO - connection.py - ODBC environment and connection handles initialized successfully.
2025-01-08 16:00:03,346 - ERROR - connection.py - An error occurred during initialization: check_ret() missing 1 required positional argument: 'handle'
2025-01-08 16:00:03,347 - INFO - connection.py - Connecting to the database
2025-01-08 16:00:03,347 - INFO - __init__.py - Successfully connected to the database
2025-01-08 16:00:03,347 - ERROR - connection.py - An error occurred while connecting to the database: exception: access violation reading 0x0000000000000048
2025-01-08 16:00:03,347 - ERROR - __init__.py - An error occurred while connecting to the database: exception: access violation reading 0x0000000000000048
2025-01-08 16:00:29,506 - ERROR - __init__.py - An error occurred while connecting to the database: check_ret() missing 1 required positional argument: 'handle'
2025-01-08 16:01:33,595 - ERROR - __init__.py - An error occurred while connecting to the database: object of type 'int' has no len()
2025-01-08 16:02:31,795 - INFO - connection.py - Connecting to the database
2025-01-08 16:02:31,795 - INFO - __init__.py - Connecting to the database
2025-01-08 16:02:46,898 - ERROR - connection.py - An error occurred while connecting to the database: function 'SQLSMALLINT' not found
2025-01-08 16:02:46,899 - ERROR - __init__.py - An error occurred while connecting to the database: function 'SQLSMALLINT' not found
2025-01-08 16:03:27,875 - INFO - connection.py - Connecting to the database
2025-01-08 16:03:27,878 - INFO - __init__.py - Connecting to the database
2025-01-08 16:03:28,396 - INFO - connection.py - Connection established successfully.
